Failure # 1 (occurred at 2025-05-30_20-28-37)
[36mray::ImplicitFunc.train()[39m (pid=1472778, ip=37.27.65.57, actor_id=85a95d4e5a318baad7c36f9d01000000, repr=trainable)
           ^^^^^^^^^^^^^^^^^^^^^^^^^^^^^^^^^^^^
           ^^^^^^^^^^^^^^^^^^^^^^^^^^^^^^^
  File "/home/alessio/Personal/ReinforceStrategyCreatorV2/reinforcestrategycreator_pipeline/venv/lib/python3.12/site-packages/ray/tune/trainable/trainable.py", line 330, in train
    raise skipped from exception_cause(skipped)
  File "/home/alessio/Personal/ReinforceStrategyCreatorV2/reinforcestrategycreator_pipeline/venv/lib/python3.12/site-packages/ray/air/_internal/util.py", line 107, in run
    self._ret = self._target(*self._args, **self._kwargs)
                ^^^^^^^^^^^^^^^^^^^^^^^^^^^^^^^^^^^^^^^^^
  File "/home/alessio/Personal/ReinforceStrategyCreatorV2/reinforcestrategycreator_pipeline/venv/lib/python3.12/site-packages/ray/tune/trainable/function_trainable.py", line 45, in <lambda>
    training_func=lambda: self._trainable_func(self.config),
                          ^^^^^^^^^^^^^^^^^^^^^^^^^^^^^^^^^
           ^^^^^^^^^^^^^^^^^^^^^^^^^^^^^^^
  File "/home/alessio/Personal/ReinforceStrategyCreatorV2/reinforcestrategycreator_pipeline/venv/lib/python3.12/site-packages/ray/tune/trainable/function_trainable.py", line 261, in _trainable_func
    output = fn()
             ^^^^
  File "/home/alessio/Personal/ReinforceStrategyCreatorV2/reinforcestrategycreator_pipeline/src/training/hpo_optimizer.py", line 209, in trainable
    tune.report(**epoch_metrics)
  File "/home/alessio/Personal/ReinforceStrategyCreatorV2/reinforcestrategycreator_pipeline/venv/lib/python3.12/site-packages/ray/train/_internal/session.py", line 663, in wrapper
    return fn(*args, **kwargs)
           ^^^^^^^^^^^^^^^^^^^
TypeError: report() got an unexpected keyword argument 'loss'
