Failure # 1 (occurred at 2025-06-07_16-31-21)
[36mray::ImplicitFunc.train()[39m (pid=3741944, ip=37.27.65.57, actor_id=cb24a6076eb639b6044509cb01000000, repr=trainable)
           ^^^^^^^^^^^^^^^^^^^^^^^^^^^^^^^^^^^^
           ^^^^^^^^^^^^^^^^^^^^^^^^^^^^^^^
  File "/home/alessio/Personal/ReinforceStrategyCreatorV2/reinforcestrategycreator_pipeline/.venv/lib/python3.12/site-packages/ray/tune/trainable/trainable.py", line 330, in train
    raise skipped from exception_cause(skipped)
  File "/home/alessio/Personal/ReinforceStrategyCreatorV2/reinforcestrategycreator_pipeline/.venv/lib/python3.12/site-packages/ray/air/_internal/util.py", line 107, in run
    self._ret = self._target(*self._args, **self._kwargs)
                ^^^^^^^^^^^^^^^^^^^^^^^^^^^^^^^^^^^^^^^^^
  File "/home/alessio/Personal/ReinforceStrategyCreatorV2/reinforcestrategycreator_pipeline/.venv/lib/python3.12/site-packages/ray/tune/trainable/function_trainable.py", line 45, in <lambda>
    training_func=lambda: self._trainable_func(self.config),
                          ^^^^^^^^^^^^^^^^^^^^^^^^^^^^^^^^^
           ^^^^^^^^^^^^^^^^^^^^^^^^^^^^^^^
  File "/home/alessio/Personal/ReinforceStrategyCreatorV2/reinforcestrategycreator_pipeline/.venv/lib/python3.12/site-packages/ray/tune/trainable/function_trainable.py", line 261, in _trainable_func
    output = fn()
             ^^^^
  File "/home/alessio/Personal/ReinforceStrategyCreatorV2/reinforcestrategycreator_pipeline/src/training/hpo_optimizer.py", line 184, in trainable
    worker_data_manager = DataManager(
                          ^^^^^^^^^^^^
  File "/home/alessio/Personal/ReinforceStrategyCreatorV2/reinforcestrategycreator_pipeline/src/data/manager.py", line 48, in __init__
    pipeline_config = config_manager.get_config()
                      ^^^^^^^^^^^^^^^^^^^^^^^^^^^
  File "/home/alessio/Personal/ReinforceStrategyCreatorV2/reinforcestrategycreator_pipeline/src/config/manager.py", line 97, in get_config
    raise RuntimeError("Configuration not loaded. Call load_config() first.")
RuntimeError: Configuration not loaded. Call load_config() first.
